Workbook

Sheet Occupancy
B1: PROJECT PEGASUS - HISTORICAL OCCUPANCY
E3: Quarter Ending
B4: Property Name | C4: Submarket | D4: Square Footage | E4: 44476 | F4: 44561 | G4: 44651 | H4: 44742 | I4: 44834 | J4: 44926 | K4: 45016 | L4: 45107 | M4: 45199 | N4: 45291 | O4: 45382 | P4: 45473 | Q4: 45565 | R4: 45657 | S4: 45747 | T4: 45838 | U4: 45930 | V4: Current
B5: Reliance Broadway | C5: Airport | D5: 200813 | E5: 0.9891 | F5: 0.955 | G5: 0.96520146 | H5: 0.96520146 | I5: 0.98312858 | J5: 0.93333101 | K5: 0.94528243 | L5: 0.97117716 | M5: 0.96520146 | N5: 0.96520146 | O5: 0.97715287 | P5: 0.93333101 | Q5: 0.90544437 | R5: 0.8596306 | S5: 0.78314153 | T5: 0.79987351 | U5: 0.81471319
B6: Reliance Broadway - Building A | C6: Airport | D6: 77045 | E6: 1 | F6: 1 | G6: 1 | H6: 1 | I6: 1 | J6: 1 | K6: 1 | L6: 1 | M6: 1 | N6: 1 | O6: 1 | P6: 1 | Q6: 1 | R6: 1 | S6: 1 | T6: 1 | U6: 1
B7: Reliance Broadway - Building B | C7: Airport | D7: 107490 | E7: 1 | F7: 1 | G7: 1 | H7: 1 | I7: 1 | J7: 1 | K7: 1 | L7: 1 | M7: 1 | N7: 1 | O7: 1 | P7: 1 | Q7: 1 | R7: 1 | S7: 1 | T7: 1 | U7: 1
B8: Reliance Broadway - Building C-D-E | C8: Airport | D8: 115354 | E8: 1 | F8: 1 | G8: 1 | H8: 1 | I8: 1 | J8: 1 | K8: 1 | L8: 1 | M8: 1 | N8: 1 | O8: 0.96001006 | P8: 0.96867902 | Q8: 0.96867902 | R8: 0.96399778 | S8: 1 | T8: 1 | U8: 0.96867902
B9: Reliance Broadway - Building F | C9: Airport | D9: 103094 | E9: 1 | F9: 1 | G9: 1 | H9: 1 | I9: 1 | J9: 1 | K9: 1 | L9: 1 | M9: 1 | N9: 1 | O9: 1 | P9: 1 | Q9: 1 | R9: 1 | S9: 1 | T9: 1 | U9: 1
B10: Reliance Broadway | D10: =+D9+D8+D7+D6+D5 -> 603796 | E10: =+SUMPRODUCT(E5:E9,$D$5:$D$9)/$D$10 -> 0.99637483 | F10: =+SUMPRODUCT(F5:F9,$D$5:$D$9)/$D$10 -> 0.98503371 | G10: =+SUMPRODUCT(G5:G9,$D$5:$D$9)/$D$10 -> 0.98842655 | H10: =+SUMPRODUCT(H5:H9,$D$5:$D$9)/$D$10 -> 0.98842655 | I10: =+SUMPRODUCT(I5:I9,$D$5:$D$9)/$D$10 -> 0.99438883 | J10: =+SUMPRODUCT(J5:J9,$D$5:$D$9)/$D$10 -> 0.97782695 | K10: =+SUMPRODUCT(K5:K9,$D$5:$D$9)/$D$10 -> 0.9818018 | L10: =+SUMPRODUCT(L5:L9,$D$5:$D$9)/$D$10 -> 0.99041398 | ... U10: =+SUMPRODUCT(U5:U9,$D$5:$D$9)/$D$10 -> 0.93239273 | V10: =(Occupancy!D10-SUM('Occupancy Summary Schedule'!F4:F8))/Occupancy!D10 -> 0.92367124
A11: 880904 | B11: South 40 | C11: Airport | D11: 84412 | E11: 1 | F11: 1 | G11: 1 | H11: 1 | I11: 1 | J11: 1 | K11: 1 | L11: 1 | M11: 0.92607686 | N11: 0.96777709 | O11: 0.96777709 | P11: 1 | Q11: 0.88139127 | R11: 0.88139127 | S11: 0.9631569 | T11: 0.89918495 | U11: 0.8745439 | V11: ='Occupancy Summary Schedule'!E10 -> 0.8745439
B12: AIRPORT SUB-TOTAL | D12: =+D10+D11 -> 688208 | E12: =+SUMPRODUCT(E10:E11,$D$10:$D$11)/$D$12 -> 0.99681948 | F12: =+SUMPRODUCT(F10:F11,$D$10:$D$11)/$D$12 -> 0.9868694 | G12: =+SUMPRODUCT(G10:G11,$D$10:$D$11)/$D$12 -> 0.98984609 | H12: =+SUMPRODUCT(H10:H11,$D$10:$D$11)/$D$12 -> 0.98984609 | I12: =+SUMPRODUCT(I10:I11,$D$10:$D$11)/$D$12 -> 0.99507707 | J12: =+SUMPRODUCT(J10:J11,$D$10:$D$11)/$D$12 -> 0.98054658 | K12: =+SUMPRODUCT(K10:K11,$D$10:$D$11)/$D$12 -> 0.9840339 | L12: =+SUMPRODUCT(L10:L11,$D$10:$D$11)/$D$12 -> 0.99158975 | ... U12: =+SUMPRODUCT(U10:U11,$D$10:$D$11)/$D$12 -> 0.92529729 | V12: ='Occupancy Summary Schedule'!E11 -> 0.91764554
B14: Golden Key Plaza | C14: Chandler Gilbert | D14: 63714 | E14: 0.919 | F14: 0.90777537 | G14: 0.97377342 | H14: 1 | I14: 0.98130709 | J14: 0.98130709 | K14: 1 | L14: 1 | M14: 1 | N14: 0.98130709 | O14: 0.96073077 | P14: 0.92957592 | Q14: 0.96073077 | R14: 0.89711837 | S14: 0.90827762 | T14: 0.91893461 | U14: 0.94516119 | V14: ='Occupancy Summary Schedule'!E13 -> 0.94261858
B15: Chandler Technology Center | C15: Chandler Gilbert | D15: 113000 | E15: 0.965 | F15: 1 | G15: 0.93654867 | H15: 0.9359292 | I15: 0.9359292 | J15: 0.9359292 | K15: 0.9359292 | L15: 0.9359292 | M15: 0.9359292 | N15: 0.9359292 | O15: 0.94942478 | P15: 0.90888496 | Q15: 0.94219469 | R15: 0.94219469 | S15: 1 | T15: 1 | U15: 0.92911504 | V15: ='Occupancy Summary Schedule'!E14 -> 0.88383186
B16: Chicago Street Business Park | C16: Chandler Gilbert | D16: 54382 | E16: 1 | F16: 1 | G16: 1 | H16: 0.95426796 | I16: 0.90853591 | J16: 1 | K16: 1 | L16: 1 | M16: 1 | N16: 1 | O16: 1 | P16: 1 | Q16: 1 | R16: 1 | S16: 0.9451289 | T16: 0.60795852 | U16: 0.9421132 | V16: ='Occupancy Summary Schedule'!E15 -> 0.90853591
B17: Fiesta Center | C17: Chandler Gilbert | D17: 122693 | E17: 1 | F17: 0.938 | G17: 0.98384586 | H17: 0.98061829 | I17: 1 | J17: 0.96656696 | K17: 0.98425338 | L17: 1 | M17: 0.9818327 | N17: 1 | O17: 1 | P17: 1 | Q17: 1 | R17: 0.92834147 | S17: 0.92389134 | T17: 0.94327305 | U17: 0.73978141 | V17: ='Occupancy Summary Schedule'!E16 -> 0.75552803
B18: Fiesta Ranch Business Center | C18: Chandler Gilbert | D18: 56520 | E18: 1 | F18: 1 | G18: 1 | H18: 1 | I18: 1 | J18: 1 | K18: 1 | L18: 1 | M18: 0.84962845 | N18: 0.94803609 | O18: 1 | P18: 1 | Q18: 1 | R18: 1 | S18: 1 | T18: 1 | U18: 1 | V18: ='Occupancy Summary Schedule'!E17 -> 1
B19: Frye Road Business Center | C19: Chandler Gilbert | D19: 73291 | E19: 1 | F19: 0.981 | G19: 0.96425209 | H19: 1 | I19: 1 | J19: 1 | K19: 1 | L19: 0.98188045 | M19: 0.98188045 | N19: 0.9388738 | O19: 0.86110164 | P19: 0.90094282 | Q19: 0.78302929 | R19: 0.84360972 | S19: 0.90473592 | T19: 0.90066993 | U19: 0.84036239 | V19: ='Occupancy Summary Schedule'!E18 -> 0.84036239
B20: Oakland Business Park | C20: Chandler Gilbert | D20: 38501 | E20: 1 | F20: 1 | G20: 1 | H20: 1 | I20: 0.96093608 | J20: 1 | K20: 1 | L20: 0.95844264 | M20: 1 | N20: 1 | O20: 0.9657931 | P20: 0.9657931 | Q20: 1 | R20: 1 | S20: 1 | T20: 1 | U20: 1 | V20: ='Occupancy Summary Schedule'!E19 -> 1
B21: CHANDLER-GILBERT SUB-TOTAL | D21: =+SUM(D14:D20) -> 522101 | E21: =+SUMPRODUCT(E14:E20,$D$14:$D$20)/$D$21 -> 0.98254009 | F21: =+SUMPRODUCT(F14:F20,$D$14:$D$20)/$D$21 -> 0.9715084 | G21: =+SUMPRODUCT(G14:G20,$D$14:$D$20)/$D$21 -> 0.97425211 | H21: =+SUMPRODUCT(H14:H20,$D$14:$D$20)/$D$21 -> 0.97681483 | I21: =+SUMPRODUCT(I14:I20,$D$14:$D$20)/$D$21 -> 0.97144422 | J21: =+SUMPRODUCT(J14:J20,$D$14:$D$20)/$D$21 -> 0.97599507 | K21: =+SUMPRODUCT(K14:K20,$D$14:$D$20)/$D$21 -> 0.98243252 | L21: =+SUMPRODUCT(L14:L20,$D$14:$D$20)/$D$21 -> 0.98052484 | ... U21: =+SUMPRODUCT(U14:U20,$D$14:$D$20)/$D$21 -> 0.888376 | V21: ='Occupancy Summary Schedule'!E20 -> 0.87846796
B23: Central Deer Valley | C23: Deer Valley | D23: 52560 | E23: 1 | F23: 1 | G23: 1 | H23: 1 | I23: 1 | J23: 0.9766933 | K23: 0.93007991 | L23: 1 | M23: 1 | N23: 1 | O23: 1 | P23: 0.92161339 | Q23: 0.92161339 | R23: 0.88242009 | S23: 0.81992009 | T23: 0.81992009 | U23: 0.88242009 | V23: ='Occupancy Summary Schedule'!E22 -> 0.92161339
B24: Deer Valley Commerce Center | C24: Deer Valley | D24: 214400 | E24: 1 | F24: 1 | G24: 0.9591 | H24: 1 | I24: 0.98635728 | J24: 0.91512127 | K24: 1 | L24: 1 | M24: 0.98635728 | N24: 0.94240672 | O24: 0.94316231 | P24: 0.98560168 | Q24: 0.98635728 | R24: 0.94391791 | S24: 0.89010261 | T24: 0.86281716 | U24: 0.84776586 | V24: ='Occupancy Summary Schedule'!E23 -> 0.87645989
B25: Desert Ridge Industrial Park | C25: Deer Valley | D25: 52715 | E25: 1 | F25: 1 | G25: 1 | H25: 1 | I25: 1 | J25: 1 | K25: 1 | L25: 1 | M25: 1 | N25: 1 | O25: 1 | P25: 1 | Q25: 1 | R25: 1 | S25: 1 | T25: 1 | U25: 0.53343451 | V25: ='Occupancy Summary Schedule'!E24 -> 0.87597458
B26: Laser Drive Industrial | C26: Deer Valley | D26: 35597 | E26: 1 | F26: 1 | G26: 0.96451948 | H26: 0.93926454 | I26: 0.93926454 | J26: 0.93926454 | K26: 1 | L26: 1 | M26: 0.97022221 | N26: 1 | O26: 0.93926454 | P26: 0.93926454 | Q26: 1 | R26: 1 | S26: 1 | T26: 0.94505155 | U26: 0.88032699 | V26: ='Occupancy Summary Schedule'!E25 -> 0.84307666
B27: Perimeter Center | C27: Deer Valley | D27: 84028 | E27: 1 | F27: 0.9768 | G27: 0.97680535 | H27: 0.95599086 | I27: 0.95599086 | J27: 1 | K27: 1 | L27: 0.95288475 | M27: 0.95288475 | N27: 0.89091731 | O27: 0.81901271 | P27: 0.77500357 | Q27: 0.74975008 | R27: 0.84690817 | S27: 1 | T27: 1 | U27: 1 | V27: ='Occupancy Summary Schedule'!E26 -> 1
B28: Rose Garden Business Center | C28: Deer Valley | D28: 71016 | E28: 1 | F28: 0.9376 | G28: 0.96522954 | H28: 1 | I28: 1 | J28: 1 | K28: 1 | L28: 1 | M28: 1 | N28: 0.9718655 | O28: 1 | P28: 1 | Q28: 1 | R28: 0.95950208 | S28: 0.98593275 | T28: 0.96993635 | U28: 0.9732173 | V28: ='Occupancy Summary Schedule'!E27 -> 0.97040104
B29: DEER VALLEY SUB-TOTAL | D29: =+SUM(D23:D28) -> 510316 | E29: =+SUMPRODUCT(E23:E28,$D$23:$D$28)/$D$29 -> 1 | F29: =+SUMPRODUCT(F23:F28,$D$23:$D$28)/$D$29 -> 0.98749628 | G29: =+SUMPRODUCT(G23:G28,$D$23:$D$28)/$D$29 -> 0.97168378 | H29: =+SUMPRODUCT(H23:H28,$D$23:$D$28)/$D$29 -> 0.98851692 | I29: =+SUMPRODUCT(I23:I28,$D$23:$D$28)/$D$29 -> 0.98278518 | J29: =+SUMPRODUCT(J23:J28,$D$23:$D$28)/$D$29 -> 0.95770268 | K29: =+SUMPRODUCT(K23:K28,$D$23:$D$28)/$D$29 -> 0.99279858 | L29: =+SUMPRODUCT(L23:L28,$D$23:$D$28)/$D$29 -> 0.99224206 | ... U29: =+SUMPRODUCT(U23:U28,$D$23:$D$28)/$D$29 -> 0.86366095 | V29: ='Occupancy Summary Schedule'!E28 -> 0.91214659
B31: Falcon Field Industrial | C31: Mesa | D31: 40860 | E31: 1 | F31: 1 | G31: 1 | H31: 1 | I31: 1 | J31: 0.94517866 | K31: 1 | L31: 0.94517866 | M31: 1 | N31: 1 | O31: 1 | P31: 1 | Q31: 1 | R31: 1 | S31: 1 | T31: 1 | U31: 0.94517866 | V31: ='Occupancy Summary Schedule'!E30 -> 1
B32: Horne Commerce Center | C32: Mesa | D32: 59408 | E32: 0.9659 | F32: 1 | G32: 1 | H32: 1 | I32: 0.96323727 | J32: 1 | K32: 1 | L32: 1 | M32: 0.96323727 | N32: 1 | O32: 0.96323727 | P32: 0.96586318 | Q32: 0.96586318 | R32: 0.96586318 | S32: 1 | T32: 1 | U32: 0.8345004 | V32: ='Occupancy Summary Schedule'!E31 -> 0.87126313
B33: Mesa Business Park | C33: Mesa | D33: 64619 | E33: 0.9609 | F33: 1 | G33: 1 | H33: 0.96092481 | I33: 1 | J33: 1 | K33: 1 | L33: 0.88526594 | M33: 1 | N33: 0.96092481 | O33: 0.96227116 | P33: 0.92299478 | Q33: 0.84349804 | R33: 0.88257324 | S33: 0.72896517 | T33: 0.72896517 | U33: 0.68988997 | V33: ='Occupancy Summary Schedule'!E32 -> 0.80597038
B34: Southpoint Commerce Center | C34: Mesa | D34: 59194 | E34: 0.9673 | F34: 0.947 | G34: 0.96731088 | H34: 0.97712606 | I34: 0.97021658 | J34: 0.9191641 | K34: 0.9191641 | L34: 0.9191641 | M34: 0.95126195 | N34: 0.96942258 | O34: 0.94541677 | P34: 0.94541677 | Q34: 0.94594047 | R34: 0.91894449 | S34: 0.91894449 | T34: 0.96731088 | U34: 0.94443694 | V34: ='Occupancy Summary Schedule'!E33 -> 1
B35: Aero I | C35: Mesa | D35: 58816 | E35: 1 | F35: 1 | G35: 1 | H35: 1 | I35: 1 | J35: 1 | K35: 1 | L35: 1 | M35: 1 | N35: 1 | O35: 1 | P35: 1 | Q35: 0.84820457 | R35: 0.9171994 | S35: 1 | T35: 1 | U35: 1 | V35: ='Occupancy Summary Schedule'!E34 -> 0.68238234
B36: MESA SUB-TOTAL | D36: =+SUM(D31:D35) -> 282897 | E36: =+SUMPRODUCT(E31:E35,$D$31:$D$35)/$D$36 -> 0.97706565 | F36: =+SUMPRODUCT(F31:F35,$D$31:$D$35)/$D$36 -> 0.98891016 | G36: =+SUMPRODUCT(G31:G35,$D$31:$D$35)/$D$36 -> 0.99316005 | H36: =+SUMPRODUCT(H31:H35,$D$31:$D$35)/$D$36 -> 0.9862883 | I36: =+SUMPRODUCT(I31:I35,$D$31:$D$35)/$D$36 -> 0.98604793 | J36: =+SUMPRODUCT(J31:J35,$D$31:$D$35)/$D$36 -> 0.97516764 | K36: =+SUMPRODUCT(K31:K35,$D$31:$D$35)/$D$36 -> 0.98308572 | L36: =+SUMPRODUCT(L31:L35,$D$31:$D$35)/$D$36 -> 0.94896022 | ... U36: =+SUMPRODUCT(U31:U35,$D$31:$D$35)/$D$36 -> 0.87486612 | V36: ='Occupancy Summary Schedule'!E35 -> 0.86261077
B38: Broadway Industrial | C38: Tempe | D38: 43963 | E38: 0.98337238 | F38: 0.983 | G38: 0.92648363 | H38: 1 | I38: 1 | J38: 0.98337238 | K38: 1 | L38: 1 | M38: 1 | N38: 0.943134 | O38: 1 | P38: 1 | Q38: 1 | R38: 1 | S38: 0.829402 | T38: 0.772536 | U38: 0.65880399 | V38: ='Occupancy Summary Schedule'!E37 -> 0.71567
B39: Hayden Park | C39: Tempe | D39: 100134 | E39: 1 | F39: 1 | G39: 0.9857491 | H39: 1 | I39: 1 | J39: 1 | K39: 1 | L39: 0.96944095 | M39: 1 | N39: 1 | O39: 0.97009008 | P39: 0.97009008 | Q39: 0.92132542 | R39: 0.92132542 | S39: 0.93557633 | T39: 0.90606587 | U39: 0.90606587 | V39: ='Occupancy Summary Schedule'!E38 -> 0.85781053
B40: Hardy Center | C40: Tempe | D40: 49277 | E40: 1 | F40: 0.94407127 | G40: 1 | H40: 1 | I40: 1 | J40: 1 | K40: 1 | L40: 1 | M40: 0.95438034 | N40: 0.97236033 | O40: 0.97236033 | P40: 1 | Q40: 0.88221686 | R40: 0.95438034 | S40: 0.95438034 | T40: 0.95438034 | U40: 0.95438034 | V40: ='Occupancy Summary Schedule'!E39 -> 0.76516428
B41: Park Lane | C41: Tempe | D41: 51040 | E41: 0.96598746 | F41: 0.96598746 | G41: 0.94604232 | H41: 1 | I41: 1 | J41: 1 | K41: 1 | L41: 1 | M41: 0.97452978 | N41: 0.97452978 | O41: 1 | P41: 1 | Q41: 1 | R41: 0.93030956 | S41: 0.96598746 | T41: 0.96598746 | U41: 0.96598746 | V41: ='Occupancy Summary Schedule'!E40 -> 0.96598746
A42: 975543 | B42: University Business Center | C42: Tempe | D42: 34473 | E42: 1 | F42: 1 | G42: 1 | H42: 1 | I42: 1 | J42: 1 | K42: 1 | L42: 1 | M42: 1 | N42: 1 | O42: 1 | P42: 0.95660372 | Q42: 0.95660372 | R42: 1 | S42: 1 | T42: 1 | U42: 1 | V42: ='Occupancy Summary Schedule'!E41 -> 0.59991878
B43: TEMPE SUB-TOTAL | D43: =+SUM(D38:D42) -> 278887 | E43: =+SUMPRODUCT(E38:E42,$D$38:$D$42)/$D$43 -> 0.99115412 | F43: =+SUMPRODUCT(F38:F42,$D$38:$D$42)/$D$43 -> 0.98121328 | G43: =+SUMPRODUCT(G38:G42,$D$38:$D$42)/$D$43 -> 0.97341934 | H43: =+SUMPRODUCT(H38:H42,$D$38:$D$42)/$D$43 -> 1 | I43: =+SUMPRODUCT(I38:I42,$D$38:$D$42)/$D$43 -> 1 | J43: =+SUMPRODUCT(J38:J42,$D$38:$D$42)/$D$43 -> 0.99737887 | K43: =+SUMPRODUCT(K38:K42,$D$38:$D$42)/$D$43 -> 1 | L43: =+SUMPRODUCT(L38:L42,$D$38:$D$42)/$D$43 -> 0.98902781 | ... U43: =+SUMPRODUCT(U38:U42,$D$38:$D$42)/$D$43 -> 0.8982025 | V43: ='Occupancy Summary Schedule'!E42 -> 0.80695407
B47: SUMMARY
B48: Sub-Market | D48: Sq. Ft. | E48: Occupancy at Acquisition | F48: 44561 | G48: 44651 | H48: 44742 | I48: 44834 | J48: 44926 | K48: 45016 | L48: 45107 | M48: 45199 | N48: 45291 | O48: 45382 | P48: 45473 | Q48: =Q4 -> 45565 | R48: =R4 -> 45657 | S48: =S4 -> 45747 | T48: =T4 -> 45838 | U48: =U4 -> 45930 | V48: Current
...

Sheet Sheet1
A1: [
A2: {"Submarket": "Airport", "Total SF": 688208, "Vacant SF": 56677, "Occupancy": 0.9176, "SF Expiring in Next 6 Months": null, "% Expiring in Next 6 Months": null, "Pending Deals": 15240, "Vacant Space": 25247, "Relative Occupancy": 0.9633},
A3: {"Submarket": "Chandler-Gilbert", "Total SF": 522101, "Vacant SF": 63452, "Occupancy": 0.8785, "SF Expiring in Next 6 Months": null, "% Expiring in Next 6 Months": null, "Pending Deals": 17886, "Vacant Space": 41125, "Relative Occupancy": 0.9212},
A4: {"Submarket": "Deer Valley", "Total SF": 510316, "Vacant SF": 44833, "Occupancy": 0.9121, "SF Expiring in Next 6 Months": null, "% Expiring in Next 6 Months": null, "Pending Deals": 8775, "Vacant Space": 31073, "Relative Occupancy": 0.9391},
A5: {"Submarket": "Mesa", "Total SF": 282897, "Vacant SF": 38867, "Occupancy": 0.8626, "SF Expiring in Next 6 Months": null, "% Expiring in Next 6 Months": null, "Pending Deals": 0, "Vacant Space": 20186, "Relative Occupancy": 0.9286},
A6: {"Submarket": "Tempe", "Total SF": 278887, "Vacant SF": 53838, "Occupancy": 0.8070, "SF Expiring in Next 6 Months": null, "% Expiring in Next 6 Months": null, "Pending Deals": 10000, "Vacant Space": 43838, "Relative Occupancy": 0.8428},
A7: {"Submarket": "Totals/Weighted Average", "Total SF": 2282409, "Vacant SF": 257667, "Occupancy": 0.8871, "SF Expiring in Next 6 Months": null, "% Expiring in Next 6 Months": null, "Pending Deals": 51901, "Vacant Space": 161469, "Relative Occupancy": 0.9293}
A8: ]

Sheet Occupancy Summary Schedule
B1: Summary Schedule
B3: Property Name | C3: Submarket | D3: Square Footage | E3: Occupancy | F3: Vacant SF | G3: SF Expiring in Next 6 Months | H3: % Expiring in Next 6 Months | I3: Pending Deals | J3: Vacant
B4: Reliance Broadway | C4: Airport | D4: 200813 | E4: =IF(D4=0,"",(D4-F4)/D4) -> 0.78848979 | F4: ='551_Reliance Broadway'!E56 -> 42474 | G4: ='551_Reliance Broadway'!E30 -> 28840 | H4: =IF(D4=0,"",G4/D4) -> 0.1436162 | I4: ='551_Reliance Broadway'!C56 -> 15240 | J4: ='551_Reliance Broadway'!H56 -> 21634 | K4: =(D4-J4)/D4 -> 0.89226793
B5: Reliance Broadway - Building A | C5: Airport | D5: 77045 | E5: =IF(D5=0,"",(D5-F5)/D5) -> 1 | F5: ='551A_Reliance Broadway A'!E46 -> 0 | G5: ='551A_Reliance Broadway A'!E24 -> 9456 | H5: =IF(D5=0,"",G5/D5) -> 0.12273347 | I5: ='551A_Reliance Broadway A'!C46 -> 0 | J5: ='551A_Reliance Broadway A'!H46 -> 0 | K5: =(D5-J5)/D5 -> 1
B6: Reliance Broadway - Building B | C6: Airport | D6: 107490 | E6: =IF(D6=0,"",(D6-F6)/D6) -> 1 | F6: ='551B_Reliance Broadway B'!E46 -> 0 | G6: ='551B_Reliance Broadway B'!E24 -> 20924 | H6: =IF(D6=0,"",G6/D6) -> 0.19465997 | I6: ='551B_Reliance Broadway B'!C46 -> 0 | J6: ='551B_Reliance Broadway B'!H46 -> 0 | K6: =(D6-J6)/D6 -> 1
B7: Reliance Broadway - Building C-D-E | C7: Airport | D7: 115354 | E7: =IF(D7=0,"",(D7-F7)/D7) -> 0.96867902 | F7: ='551E_Reliance Broadway C,D,E'!E46 -> 3613 | G7: ='551E_Reliance Broadway C,D,E'!E24 -> 14587 | H7: =IF(D7=0,"",G7/D7) -> 0.12645422 | I7: ='551E_Reliance Broadway C,D,E'!C46 -> 0 | J7: ='551E_Reliance Broadway C,D,E'!H46 -> 3613 | K7: =(D7-J7)/D7 -> 0.96867902
B8: Reliance Broadway - Building F | C8: Airport | D8: 103094 | E8: =IF(D8=0,"",(D8-F8)/D8) -> 1 | F8: ='551F_Reliance Broadway F'!E46 -> 0 | H8: =IF(D8=0,"",G9/D8) -> 0 | I8: ='551F_Reliance Broadway F'!C46 -> 0 | J8: ='551F_Reliance Broadway F'!H46 -> 0 | K8: =(D8-J8)/D8 -> 1
B9: Reliance Broadway | D9: =+D8+D7+D6+D5+D4 -> 603796 | E9: =IF(D9=0,"",(D9-F9)/D9) -> 0.92367124 | F9: =SUM(F4:F8) -> 46087 | G9: ='551F_Reliance Broadway F'!E24 -> 0 | H9: =IF(D9=0,"",G10/D9) -> 0.0034448721 | I9: =SUM(I4:I8) -> 15240 | J9: =SUM(J4:J8) -> 25247 | K9: =(D9-J9)/D9 -> 0.95818621
B10: South 40 | C10: Airport | D10: 84412 | E10: =IF(D10=0,"",(D10-F10)/D10) -> 0.8745439 | F10: ='730_South 40'!E32 -> 10590 | G10: ='730_South 40'!E24 -> 2080 | H10: =IF(D10=0,"",G10/D10) -> 0.024641046 | I10: ='730_South 40'!C32 -> 0 | J10: ='730_South 40'!H32 -> 0 | K10: =(D10-J10)/D10 -> 1
B11: AIRPORT SUB-TOTAL | D11: =+D9+D10 -> 688208 | E11: =IF(D11=0,"",(D11-F11)/D11) -> 0.91764554 | F11: =SUM(F9:F10) -> 56677 | G11: =SUM(G4:G10) -> 75887 | H11: =+G11/D11 -> 0.11026754 | I11: =SUM(I9:I10) -> 15240 | J11: =SUM(J9:J10) -> 25247 | K11: =(D11-J11)/D11 -> 0.96331487
B13: Golden Key Plaza | C13: Chandler Gilbert | D13: 63714 | E13: =IF(D13=0,"",(D13-F13)/D13) -> 0.94261858 | F13: ='120_Golden Key Plaza'!E47 -> 3656 | G13: ='120_Golden Key Plaza'!E25 -> 7746 | H13: =IF(D13=0,"",G13/D13) -> 0.12157454 | I13: ='120_Golden Key Plaza'!C47 -> 0 | J13: ='120_Golden Key Plaza'!H47 -> 1985 | K13: =(D13-J13)/D13 -> 0.96884515
B14: Chandler Technology Center | C14: Chandler Gilbert | D14: 113000 | E14: =IF(D14=0,"",(D14-F14)/D14) -> 0.88383186 | F14: ='341_Chandler Tech'!E38 -> 13127 | G14: ='341_Chandler Tech'!E17 -> 10393 | H14: =IF(D14=0,"",G14/D14) -> 0.091973451 | I14: ='341_Chandler Tech'!C38 -> 0 | J14: ='341_Chandler Tech'!H38 -> 10357 | K14: =(D14-J14)/D14 -> 0.90834513
B15: Chicago Street Business Park | C15: Chandler Gilbert | D15: 54382 | E15: =IF(D15=0,"",(D15-F15)/D15) -> 0.90853591 | F15: ='350 Chicago'!E39 -> 4974 | G15: ='350 Chicago'!E17 -> 7461 | H15: =IF(D15=0,"",G15/D15) -> 0.13719613 | I15: ='350 Chicago'!C39 -> 0 | J15: ='350 Chicago'!H39 -> 4974 | K15: =(D15-J15)/D15 -> 0.90853591
B16: Fiesta Center | C16: Chandler Gilbert | D16: 122693 | E16: =IF(D16=0,"",(D16-F16)/D16) -> 0.75552803 | F16: ='503_Fiesta Center'!E43 -> 29995 | G16: ='503_Fiesta Center'!E21 -> 19751 | H16: =IF(D16=0,"",G16/D16) -> 0.16097903 | I16: ='503_Fiesta Center'!C43 -> 17886 | J16: ='503_Fiesta Center'!H43 -> 12109 | K16: =(D16-J16)/D16 -> 0.90130651
B17: Fiesta Ranch Business Center | C17: Chandler Gilbert | D17: 56520 | E17: =IF(D17=0,"",(D17-F17)/D17) -> 1 | F17: ='511_Fiesta Ranch'!E31 -> 0 | G17: ='511_Fiesta Ranch'!E24 -> 2937 | H17: =IF(D17=0,"",G17/D17) -> 0.051963907 | I17: ='511_Fiesta Ranch'!C31 -> 0 | J17: ='511_Fiesta Ranch'!H31 -> 0 | K17: =(D17-J17)/D17 -> 1
B18: Frye Road Business Center | C18: Chandler Gilbert | D18: 73291 | E18: =IF(D18=0,"",(D18-F18)/D18) -> 0.84036239 | F18: ='525_Frye Road'!E45 -> 11700 | G18: ='525_Frye Road'!E24 -> 4140 | H18: =IF(D18=0,"",G18/D18) -> 0.056487154 | I18: ='525_Frye Road'!C45 -> 0 | J18: ='525_Frye Road'!H45 -> 11700 | K18: =(D18-J18)/D18 -> 0.84036239
B19: Oakland Business Park | C19: Chandler Gilbert | D19: 38501 | E19: =IF(D19=0,"",(D19-F19)/D19) -> 1 | F19: ='605_Oakland'!E31 -> 0 | G19: ='605_Oakland'!E24 -> 4608 | H19: =IF(D19=0,"",G19/D19) -> 0.1196852 | I19: ='605_Oakland'!C31 -> 0 | J19: ='605_Oakland'!H31 -> 0 | K19: =(D19-J19)/D19 -> 1
B20: CHANDLER-GILBERT SUB-TOTAL | D20: =+SUM(D13:D19) -> 522101 | E20: =IF(D20=0,"",(D20-F20)/D20) -> 0.87846796 | F20: =SUM(F13:F19) -> 63452 | G20: =SUM(G13:G19) -> 57036 | H20: =+G20/D20 -> 0.10924323 | I20: =SUM(I13:I19) -> 17886 | J20: =SUM(J13:J19) -> 41125 | K20: =(D20-J20)/D20 -> 0.92123172
B22: Central Deer Valley | C22: Deer Valley | D22: 52560 | E22: =IF(D22=0,"",(D22-F22)/D22) -> 0.92161339 | F22: ='336_Central Deer Valley'!E38 -> 4120 | G22: ='336_Central Deer Valley'!E20 -> 3675 | H22: =IF(D22=0,"",G22/D22) -> 0.069920091 | I22: ='336_Central Deer Valley'!C38 -> 0 | J22: ='336_Central Deer Valley'!H38 -> 2060 | K22: =(D22-J22)/D22 -> 0.9608067
B23: Deer Valley Commerce Center | C23: Deer Valley | D23: 214400 | E23: =IF(D23=0,"",(D23-F23)/D23) -> 0.87645989 | F23: ='370 Deer Valley Commerce'!E39 -> 26487 | G23: ='370 Deer Valley Commerce'!E17 -> 15435 | H23: =IF(D23=0,"",G23/D23) -> 0.071991604 | I23: ='370 Deer Valley Commerce'!C39 -> 8775 | J23: ='370 Deer Valley Commerce'!H39 -> 14787 | K23: =(D23-J23)/D23 -> 0.93103078
B24: Desert Ridge Industrial Park | C24: Deer Valley | D24: 52715 | E24: =IF(D24=0,"",(D24-F24)/D24) -> 0.87597458 | F24: ='375_Desert Ridge'!E38 -> 6538 | G24: ='375_Desert Ridge'!E17 -> 4509 | H24: =IF(D24=0,"",G24/D24) -> 0.085535426 | I24: ='375_Desert Ridge'!C38 -> 0 | J24: ='375_Desert Ridge'!H38 -> 6538 | K24: =(D24-J24)/D24 -> 0.87597458
B25: Laser Drive Industrial | C25: Deer Valley | D25: 35597 | E25: =IF(D25=0,"",(D25-F25)/D25) -> 0.84307666 | F25: ='548_Laser Drive'!E46 -> 5586 | G25: ='548_Laser Drive'!E24 -> 3865 | H25: =IF(D25=0,"",G25/D25) -> 0.10857657 | I25: ='548_Laser Drive'!C46 -> 0 | J25: ='548_Laser Drive'!H46 -> 5586 | K25: =(D25-J25)/D25 -> 0.84307666
B26: Perimeter Center | C26: Deer Valley | D26: 84028 | E26: =IF(D26=0,"",(D26-F26)/D26) -> 1 | F26: ='640_Perimeter Center'!E46 -> 0 | G26: ='640_Perimeter Center'!E24 -> 27824 | H26: =IF(D26=0,"",G26/D26) -> 0.33112772 | I26: ='640_Perimeter Center'!C46 -> 0 | J26: ='640_Perimeter Center'!H46 -> 0 | K26: =(D26-J26)/D26 -> 1
B27: Rose Garden Business Center | C27: Deer Valley | D27: 71016 | E27: =IF(D27=0,"",(D27-F27)/D27) -> 0.97040104 | F27: ='668_Rose Garden'!E46 -> 2102 | G27: ='668_Rose Garden'!E24 -> 8707 | H27: =IF(D27=0,"",G27/D27) -> 0.12260617 | I27: ='668_Rose Garden'!C46 -> 0 | J27: ='668_Rose Garden'!H46 -> 2102 | K27: =(D27-J27)/D27 -> 0.97040104
B28: DEER VALLEY SUB-TOTAL | D28: =+SUM(D22:D27) -> 510316 | E28: =IF(D28=0,"",(D28-F28)/D28) -> 0.91214659 | F28: =SUM(F22:F27) -> 44833 | G28: =SUM(G21:G27) -> 64015 | H28: =+G28/D28 -> 0.12544188 | I28: =SUM(I22:I27) -> 8775 | J28: =SUM(J22:J27) -> 31073 | K28: =(D28-J28)/D28 -> 0.93911028
B30: Falcon Field Industrial | C30: Mesa | D30: 40860 | E30: =IF(D30=0,"",(D30-F30)/D30) -> 1 | F30: ='508_Falcon Industrial'!E46 -> 0 | G30: ='508_Falcon Industrial'!E24 -> 8480 | H30: =IF(D30=0,"",G30/D30) -> 0.20753793 | I30: ='508_Falcon Industrial'!C46 -> 0 | J30: ='508_Falcon Industrial'!H46 -> 0 | K30: =(D30-J30)/D30 -> 1
B31: Horne Commerce Center | C31: Mesa | D31: 59408 | E31: =IF(D31=0,"",(D31-F31)/D31) -> 0.87126313 | F31: ='538_Horne'!E46 -> 7648 | G31: ='538_Horne'!E24 -> 8536 | H31: =IF(D31=0,"",G31/D31) -> 0.14368435 | I31: ='538_Horne'!C46 -> 0 | J31: ='538_Horne'!H46 -> 7648 | K31: =(D31-J31)/D31 -> 0.87126313
B32: Mesa Business Park | C32: Mesa | D32: 64619 | E32: =IF(D32=0,"",(D32-F32)/D32) -> 0.80597038 | F32: ='585_Mesa Business Park'!E46 -> 12538 | G32: ='585_Mesa Business Park'!E24 -> 7488 | H32: =IF(D32=0,"",G32/D32) -> 0.11587923 | I32: ='585_Mesa Business Park'!C46 -> 0 | J32: ='585_Mesa Business Park'!H46 -> 12538 | K32: =(D32-J32)/D32 -> 0.80597038
B33: Southpoint Commerce Center | C33: Mesa | D33: 59194 | E33: =IF(D33=0,"",(D33-F33)/D33) -> 1 | F33: ='735_Southpoint'!E46 -> 0 | G33: ='735_Southpoint'!E24 -> 9757 | H33: =IF(D33=0,"",G33/D33) -> 0.1648309 | I33: ='735_Southpoint'!C46 -> 0 | J33: ='735_Southpoint'!H46 -> 0 | K33: =(D33-J33)/D33 -> 1
B34: Aero I | C34: Mesa | D34: 58816 | E34: =IF(D34=0,"",(D34-F34)/D34) -> 0.68238234 | F34: ='805_Aero'!E29 -> 18681 | G34: ='805_Aero'!E19 -> 11729 | H34: =IF(D34=0,"",G34/D34) -> 0.19941853 | I34: ='805_Aero'!C29 -> 0 | J34: ='805_Aero'!H29 -> 0 | K34: =(D34-J34)/D34 -> 1
B35: MESA SUB-TOTAL | D35: =+SUM(D30:D34) -> 282897 | E35: =IF(D35=0,"",(D35-F35)/D35) -> 0.86261077 | F35: =SUM(F30:F34) -> 38867 | G35: =SUM(G28:G34) -> 110005 | H35: =+G35/D35 -> 0.38885177 | I35: =SUM(I30:I34) -> 0 | J35: =SUM(J30:J34) -> 20186 | K35: =(D35-J35)/D35 -> 0.92864541
B37: Broadway Industrial | C37: Tempe | D37: 43963 | E37: =IF(D37=0,"",(D37-F37)/D37) -> 0.71567 | F37: ='167_Broadway'!E40 -> 12500 | G37: ='167_Broadway'!E21 -> 5000 | H37: =IF(D37=0,"",G37/D37) -> 0.113732 | I37: ='167_Broadway'!C40 -> 10000 | J37: ='167_Broadway'!H40 -> 2500 | K37: =(D37-J37)/D37 -> 0.943134
B38: Hayden Park | C38: Tempe | D38: 100134 | E38: =IF(D38=0,"",(D38-F38)/D38) -> 0.85781053 | F38: ='537_Hayden Park'!E46 -> 14238 | G38: ='537_Hayden Park'!E24 -> 29856 | H38: =IF(D38=0,"",G38/D38) -> 0.29816046 | I38: ='537_Hayden Park'!C46 -> 0 | J38: ='537_Hayden Park'!H46 -> 14238 | K38: =(D38-J38)/D38 -> 0.85781053
B39: Hardy Center | C39: Tempe | D39: 49277 | E39: =IF(D39=0,"",(D39-F39)/D39) -> 0.76516428 | F39: ='542_Hardy Center'!E46 -> 11572 | G39: ='542_Hardy Center'!E24 -> 5012 | H39: =IF(D39=0,"",G39/D39) -> 0.10171074 | I39: ='542_Hardy Center'!C46 -> 0 | J39: ='542_Hardy Center'!H46 -> 11572 | K39: =(D39-J39)/D39 -> 0.76516428
B40: Park Lane | C40: Tempe | D40: 51040 | E40: =IF(D40=0,"",(D40-F40)/D40) -> 0.96598746 | F40: ='629_Park Lane'!E46 -> 1736 | G40: ='629_Park Lane'!E24 -> 11333 | H40: =IF(D40=0,"",G40/D40) -> 0.22204154 | I40: ='629_Park Lane'!C46 -> 0 | J40: ='629_Park Lane'!H46 -> 1736 | K40: =(D40-J40)/D40 -> 0.96598746
B41: University Business Center | C41: Tempe | D41: 34473 | E41: =IF(D41=0,"",(D41-F41)/D41) -> 0.59991878 | F41: ='873_University Business'!E39 -> 13792 | G41: ='873_University Business'!E17 -> 7425 | H41: =IF(D41=0,"",G41/D41) -> 0.21538595 | I41: ='873_University Business'!C39 -> 0 | J41: ='873_University Business'!H39 -> 13792 | K41: =(D41-J41)/D41 -> 0.59991878
B42: TEMPE SUB-TOTAL | D42: =+SUM(D37:D41) -> 278887 | E42: =IF(D42=0,"",(D42-F42)/D42) -> 0.80695407 | F42: =SUM(F37:F41) -> 53838 | G42: =SUM(G35:G41) -> 168631 | H42: =+G42/D42 -> 0.60465708 | I42: =SUM(I37:I41) -> 10000 | J42: =SUM(J37:J41) -> 43838 | K42: =(D42-J42)/D42 -> 0.84281089
B46: SUMMARY
B47: Sub-Market | D47: Sq. Ft. | E47: Vacant Sq. Ft. | F47: Occupancy | I47: Pending Deals | J47: Vacant Space | K47: Relative Occupancy
B48: Airport | D48: =+D11 -> 688208 | E48: =F11 -> 56677 | F48: =E11 -> 0.91764554 | I48: =I11 -> 15240 | J48: =J11 -> 25247 | K48: =K11 -> 0.96331487
...

Sheet Working - CPI
B1: Address | C1: Ste. | D1: S.F. Available | E1: Date Suite Available | F1: Days on Market | G1: Market Effective Rent | H1: On Lock Box | I1: Lease Ready | J1: Comments | Q1: Yes | R1: No
B2: LAURA LINK
B3: RELIANCE BROADWAY
B4: $1.15-$1.35/sq ft - MG
B5: 200813
A6: 551 | B6: 3620 E Broadway Rd | C6: 14 | D6: 1420 | E6: 45931 | F6: =IF(B6="","",NOW()-E6) -> 78.527668 | G6: 1.2 | H6: Yes | I6: Yes | J6: Suite is clean and ready to be leased.
A7: 551 | B7: 3620 E Broadway Rd | C7: 4 | D7: 1422 | E7: 45962 | F7: =IF(B7="","",NOW()-E7) -> 47.527668 | G7: 1.2 | H7: Yes | I7: Yes | J7: Lease ready
A8: 551 | B8: 3620 E Broadway Rd | C8: 11 | D8: 1977 | E8: 45992 | F8: =IF(B8="","",NOW()-E8) -> 17.527668 | G8: 1.2 | H8: Yes | I8: No | J8: HVAC Inspections Needed. Paint and suite clean
A9: 551 | B9: 3620 E Broadway Rd | C9: 12 | D9: 1835 | E9: 45992 | F9: =IF(B9="","",NOW()-E9) -> 17.527668 | G9: 1.2 | H9: Yes | I9: No | J9: HVAC Inspections Needed. Paint and suite clean
A10: 551 | B10: 3620 E Broadway Rd | C10: 15 | D10: 1420 | E10: 45992 | F10: =IF(B10="","",NOW()-E10) -> 17.527668 | G10: 1.2 | H10: Yes | I10: No | J10: HVAC Inspections Needed. Paint and suite clean
A11: 551 | B11: 4203 S. 37th Street | D11: 2400 | E11: 45627 | F11: =IF(B11="","",NOW()-E11) -> 382.52767 | G11: 1.15 | H11: Yes | I11: Yes | J11: Suite was professionally cleaned. Updating interior and exterior lighting for now.
A12: 551 | B12: 4209 S. 36th Place | D12: 3200 | E12: 45383 | F12: =IF(B12="","",NOW()-E12) -> 626.52767 | G12: 1.1 | H12: Yes | I12: Yes | J12: Lease Ready - Updating WH lighting - Allied Electric
A13: 551 | B13: 4216 S 37th Street | D13: 2400 | E13: 45839 | F13: =IF(B13="","",NOW()-E13) -> 170.52767 | G13: 1.15 | H13: Yes | I13: Yes | J13: Lease ready work completed. Ready for lease.
A14: 551 | B14: 4217 S. 36th Place | D14: 3200 | E14: 45809 | F14: =IF(B14="","",NOW()-E14) -> 200.52767 | G14: 1.1 | H14: Yes | I14: Yes | J14: Suite was professionally cleaned - Updating interior and exterior lighting for now. Will include in next group of lease ready work.
A15: 551 | B15: 4219 S 37th Street | D15: 1200 | E15: 45992 | F15: =IF(B15="","",NOW()-E15) -> 17.527668 | G15: 1.15 | H15: Yes | I15: No
A16: 551 | B16: 4221 S 36th Place | D16: 2400 | E16: 45839 | F16: =IF(B16="","",NOW()-E16) -> 170.52767 | G16: 1.15 | H16: Yes | I16: Yes | J16: Issue with lighting. Need additional time to complete.
A17: 551 | B17: 4222 S 37th Street | D17: 2400 | E17: 45717 | F17: =IF(B17="","",NOW()-E17) -> 292.52767 | G17: 1.15 | H17: Yes | I17: Yes | J17: Lease ready work completed. Ready for lease.
A18: 551 | B18: 4224, 4226, 4228 S 37th Street | D18: 5600 | E18: 45964 | F18: =IF(B18="","",NOW()-E18) -> 45.527668 | G18: 1.2 | H18: Yes | I18: Yes | J18: Tenant lease expires 03/2026. Vacated space early. Deal for suite 4224 and 4226. Demo and lease ready work to be completed on suite 4228. Close passthrough between 4226-4228
A19: 551 | B19: 4226 S 36th Place | D19: 1200 | E19: 45992 | F19: =IF(B19="","",NOW()-E19) -> 17.527668 | G19: 1.15 | H19: Yes | I19: Yes | J19: Tenant will be moved out by 12/01/2025 (SD Lighting moving to 4246 37th St)
A20: 551 | B20: 4227 S 36th Place | D20: 1200 | E20: 45992 | F20: =IF(B20="","",NOW()-E20) -> 17.527668 | G20: 1.15 | H20: Yes | I20: No | J20: Suite needs paint, flooring, lighting, HVAC inspection
A21: 551 | B21: 4241 S 36th Place | D21: 1200 | E21: 45915 | F21: =IF(B21="","",NOW()-E21) -> 94.527668 | G21: 1.15 | H21: Yes | I21: Yes | J21: Needs paint, flooring, lighting.
A22: 551 | B22: 4243 S 36th Place | D22: 2400 | E22: 45719 | F22: =IF(B22="","",NOW()-E22) -> 290.52767 | G22: 1.15 | H22: Yes | I22: Yes | J22: Updating interior and exterior lighting for now. Will include in next group of lease ready work
A23: 551 | B23: 4244 S 37th Street | D23: 2400 | E23: 46023 | F23: =IF(B23="","",NOW()-E23) -> -13.472332 | G23: 1.15 | H23: No | I23: No | J23: T. W. Garage Pros Vacating
A24: 551 | B24: 4246 S 36th Place | D24: 3200 | E24: 45839 | F24: =IF(B24="","",NOW()-E24) -> 170.52767 | G24: 1.1 | H24: Yes | I24: Yes | J24: Needs update on flooring and paint. LED has been upgraded throughout.
B25: TOTAL | D25: =+SUM(D6:D16) -> 22874 | E25: =+D25/B5 -> 0.11390697 | F25: =+IF(E25=0,"100% LEASED","")
B27: RELIANCE BROADWAY A
B28: $1.30/sq ft - NNN
B29: 77045
F32: =IF(B32="","",NOW()-E32)
F33: =IF(B33="","",NOW()-E33)
F34: =IF(B34="","",NOW()-E34)
F35: =IF(B35="","",NOW()-E35)
F36: =IF(B36="","",NOW()-E36)
F37: =IF(B37="","",NOW()-E37)
F38: =IF(B38="","",NOW()-E38)
F39: =IF(B39="","",NOW()-E39)
F40: =IF(B40="","",NOW()-E40)
F41: =IF(B41="","",NOW()-E41)
F42: =IF(B42="","",NOW()-E42)
F43: =IF(B43="","",NOW()-E43)
...

Sheet Lease Report 2025
A1: Type of Lease (New, Renewal,Expansion, Expansion and Renewal) ( R N X RX) | B1: Property | C1: Property Name | D1: Notice Address | E1: Units | F1: City, State, Zip | G1: Lease Area | H1: Tenant Entity | I1: Current Rent | J1: PSF Current | K1: First Year Rent | L1: PSF First Year | M1: Percentage increase | N1: Annual Increase | O1: CPI Notes | P1: Term | Q1: EXP | R1: Lease Commencment Date
A2: RX | B2: 120 | C2: Golden Key Plaza | D2: 751 N Monterey | E2: 113 | F2: Gilbert, AZ | G2: 1191 | H2: Scale X Pro LLC | I2: 1429.2 | J2: =I2/G2 -> 1.2 | K2: 3239.52 | L2: =K2/G2 -> 2.72 | M2: =(K2/I2)-1 -> 1.2666667 | N2: 0.07 | O2: Minor TI, No Free rent, No outside agent, Base Year Gross | P2: 3 | Q2: 45688 | R2: 45689
A3: New | B3: 120 | C3: Golden Key Plaza | D3: 425 W Guadalupe | E3: 114 | F3: Lease | G3: 2502 | H3: Luxe Cabinetry | K3: =G3*L3 -> 3127.5 | L3: 1.25 | N3: 0.06 | O3: 3 | P3: 3 | R3: 45748
A4: R | B4: 120 | C4: Golden Key Plaza | D4: 425 W Guadalupe | E4: 115, 116 | F4: Gilbert, AZ | G4: 3494 | H4: JRL Goods LLC | I4: 3852.14 | J4: =I4/G4 -> 1.1025014 | K4: 4751.84 | L4: =K4/G4 -> 1.36 | M4: =(K4/I4)-1 -> 0.23355849 | N4: 0.07 | O4: No TI, No Free rent, No outside agent, Base Year Gross | P4: 3 | Q4: 45777 | R4: 45778
A5: R | B5: 120 | C5: Golden Key Plaza | D5: 751 N Monterey | E5: 114 | F5: Gilbert, AZ | G5: 1191 | H5: Eagle One Appliance Repair | I5: 1310.1 | J5: =I5/G5 -> 1.1 | K5: 1679.31 | L5: =K5/G5 -> 1.41 | M5: =(K5/I5)-1 -> 0.28181818 | N5: 0.07 | O5: No TI, No Free rent, No outside agent, Base Year Gross | P5: 3 | Q5: 45838 | R5: 45839
A6: New | B6: 120 | C6: Golden Key Plaza | D6: 761 N Monterey | E6: 103 | F6: Lease | G6: 1671 | H6: Joshua Daniel Brown d/b/a Superstition Merch | K6: =G6*L6 -> 2088.75 | L6: 1.25 | N6: 0.05 | P6: 2 | R6: 45901
A7: R | B7: 120 | C7: Golden Key Plaza | D7: 761 N Monterey St | E7: 107 | F7: Gilbert, 85233 | G7: 1676 | H7: Lamp Service Products Arizona | I7: 1743.04 | J7: =I7/G7 -> 1.04 | K7: 2178.8 | L7: =K7/G7 -> 1.3 | M7: =(K7/I7)-1 -> 0.25 | N7: 0.06 | O7: HVAC Replacement, No Free rent, No outside agent, Base Year Gross | P7: 5 | Q7: =#REF! -> #REF! | R7: 45901
A8: New | B8: 120 | C8: Golden Key Plaza | D8: 425 W. Guadalupe Road, Suite 115 | E8: 115 | F8: Lease | G8: 1784 | H8: Batti-Performance, LLC | K8: =L8*G8 -> 2319.2 | L8: 1.3 | N8: 0.05 | O8: 1 Month free | P8: 3 | R8: 45962
A9: New | B9: 120 | C9: Golden Key Plaza | D9: 425 W Guadalupe Rd Suite 116 | E9: 116 | F9: Lease | G9: 1710 | H9: Madbrows LLC | K9: =G9*L9 -> 2137.5 | L9: 1.25 | N9: 0.05 | O9: 2 | P9: 5 | R9: 45992
A10: OFS | B10: 120 | C10: Golden Key Plaza | D10: 425 W Guadalupe | E10: 113 | F10: Gilbert, AZ 85233 | G10: 1421 | H10: Miller Chiropractic Center Inc | I10: 2358.86 | J10: =I10/G10 -> 1.66 | K10: 2358.86 | L10: =K10/G10 -> 1.66 | M10: =(K10/I10)-1 -> 0 | O10: No TI, No Free rent, No outside agent, Base Year Gross | P10: 1 | Q10: 46022 | R10: 46023
A11: New | B11: 120 | C11: Golden Key Plaza | D11: 761 N Monterey | E11: 104 | F11: Lease | G11: 1671 | H11: DRT Fabrication LLC | K11: =L11*G11 -> 2255.85 | L11: 1.35 | N11: 0.05 | O11: 1 Month free | P11: 3
A12: New | B12: 120 | C12: Golden Key Plaza | G12: 1191 | H12: Kachina Contracting Corp | K12: =G12*L12 -> 0
A13: R | B13: 167 | C13: Broadway Industrial | D13: 835 W 22nd | E13: 105-107 | F13: Tempe, AZ | G13: 7500 | H13: TRUE WORLD FOODS PHOENIX, LLC ( TW FOODS LLC ) | I13: 6075 | J13: =I13/G13 -> 0.81 | K13: 8625 | L13: =K13/G13 -> 1.15 | M13: =(K13/I13)-1 -> 0.41975309 | N13: 0.05 | O13: No TI, No Free rent, No outside agent, Base Year Gross | P13: 5 | Q13: 45900 | R13: 45901
A14: R | B14: 336 | C14: Central Deer Valley | D14: 21616 N Central Ave | F14: Phoenix, AZ 85024 | G14: 1225 | H14: Claude Bryant | I14: 1335.25 | J14: =I14/G14 -> 1.09 | K14: 1715 | L14: =K14/G14 -> 1.4 | M14: 0.28 | N14: 0.06 | O14: Tenant signed 3 year renewal | P14: 3 | Q14: 45688 | R14: 45689
A15: New | B15: 336 | C15: Central Deer Valley | D15: 21616 N Centerl | E15: 16 | F15: Lease | G15: 1225 | H15: James Cartwright a/b/a Vision Scape | K15: =G15*L15 -> 1800.75 | L15: 1.47 | N15: 0.05 | O15: 2 | P15: 5 | R15: 45748
A16: New | B16: 336 | C16: Central Deer Valley | D16: 21628 N Central | E16: 8 | F16: Lease | G16: 2060 | H16: Quiiriego Restaurant, LLC | K16: =G16*L16 -> 2925.2 | L16: 1.42 | N16: 0.085 | O16: 1 | P16: 3 | R16: 45748
A17: R | B17: 336 | C17: Central Deer Valley | D17: 21616 N Central Ave | E17: 15 | F17: Phoenix, AZ 85024 | G17: 1225 | H17: Pool Barrier of AZ | I17: 1335.25 | J17: =I17/$G17 -> 1.09 | K17: 1715 | L17: =K17/$G17 -> 1.4 | M17: =(K17/I17)-1 -> 0.28440367 | N17: 0.06 | O17: Tenant agreed to a 3 year MG renewal | P17: 3 | Q17: 45747 | R17: 45748
A18: R | B18: 336 | C18: Central Deer Valley | D18: 21616 N Central Ave | E18: 5, 11, 12, 13 | F18: Phoenix, AZ 85024 | G18: 4900 | H18: Rich Interiors | I18: 5488 | J18: =I18/G18 -> 1.12 | K18: 6615 | L18: =K18/G18 -> 1.35 | M18: =(K18/I18)-1 -> 0.20535714 | N18: 0.06 | O18: Tenant agreed to a 3 year renewal - MG lease | P18: 3 | Q18: 45747 | R18: 45748
A19: R | B19: 336 | C19: Central Deer Valley | D19: 21602 N Central Ave | E19: 7 | F19: Phoenix, AZ 85024 | G19: 4120 | H19: Scudo Divers, LLC | I19: 4738 | J19: =I19/G19 -> 1.15 | K19: 5562 | L19: =K19/G19 -> 1.35 | M19: =(K19/I19)-1 -> 0.17391304 | N19: 0.06 | O19: No TI, No Free rent, No outside agent, Base Year Gross | P19: 3 | Q19: 45777 | R19: 45778
A20: R | B20: 336 | C20: Central Deer Valley | D20: 21628 N Central Ave | E20: 3 | F20: Phoenix, AZ 85024 | G20: 2060 | H20: AZ Gun Works | I20: 2245.4 | J20: =I20/G20 -> 1.09 | K20: 2678 | L20: =K20/G20 -> 1.3 | M20: =(K20/I20)-1 -> 0.19266055 | N20: 0.05 | O20: Tenant has agreed to a 5 year MG Renewal | P20: 5 | Q20: 45838 | R20: 45839
A21: R | B21: 336 | C21: Central Deer Valley | D21: 21628 N Central Ave | E21: 4 & 5 | F21: Phoenix, AZ 85024 | G21: 4120 | H21: Bruno's Shooting Supply | I21: 4490.8 | J21: =I21/G21 -> 1.09 | K21: 5356 | L21: =K21/G21 -> 1.3 | M21: =(K21/I21)-1 -> 0.19266055 | N21: 0.05 | O21: Tenant has agreed to a 5 year MG Renewal | P21: 5 | Q21: 45838 | R21: 45839
A22: R | B22: 336 | C22: Central Deer Valley | D22: 21628 N Central Ave | E22: 1 & 2 | F22: Phoenix, AZ 85024 | G22: 4120 | H22: Moto Garage | I22: 4614.4 | J22: =I22/G22 -> 1.12 | K22: 5768 | L22: =K22/G22 -> 1.4 | M22: =(K22/I22)-1 -> 0.25 | N22: 0.06 | O22: Tenant has agreed to a 3 year MG Renewal | P22: 3 | Q22: 45838 | R22: 45839
A23: New | B23: 336 | C23: Central Deer Valley | D23: 21606 N Central | E23: 14 | F23: Lease | G23: 1225 | H23: Gecko Garage Doors Inc Doors | K23: =G23*L23 -> 1800.75 | L23: 1.47 | N23: 0.06 | O23: 1 | P23: 3 | R23: 45870
A24: R | B24: 336 | C24: Central Deer Valley | D24: 21602 N Central Ave | E24: 1 | F24: Phoenix, AZ 85024 | G24: 2060 | H24: Import Care Center/Benz | I24: 2472 | J24: =I24/G24 -> 1.2 | K24: 2884 | L24: =K24/G24 -> 1.4 | M24: 0.17 | N24: 0.06 | O24: Tenant signed a new 3 year MG renewal | P24: 3 | Q24: 45869 | R24: 45870
A25: New | B25: 336 | C25: Central Deer Valley | D25: 21602 N Central | E25: 5,6 | F25: Lease | G25: 4120 | H25: D&A Partners LLC | K25: =G25*L25 -> 5768 | L25: 1.4 | N25: 0.05 | O25: 0 | P25: 3 | R25: 45931
A26: RX | B26: 336 | C26: Central Deer Valley | D26: 21616 &21628 N Central Av3 | E26: 3, 4, 8 | F26: Phoneix. AZ 85024 | G26: 4510 | H26: Two Brother's Auto Restoration | I26: 4593.75 | J26: =I26/G26 -> 1.0185698 | K26: 6404.2 | L26: =K26/G26 -> 1.42 | M26: =(K26/I26)-1 -> 0.39411156 | N26: 0.06 | O26: Tenant is increasing 835 sf and signing a 3 year MG renewal | P26: 3 | Q26: 45991 | R26: 45992
A27: New | B27: 341 | C27: CHANDLER TECHNOLOGY CENTER | D27: 7402 W Detroit | E27: 100 | F27: Lease | G27: 1951 | H27: Arizona Fitness Distributors LLC | K27: =G27*L27 -> 2828.95 | L27: 1.45 | P27: 1 | R27: 45703
A28: RX | B28: 341 | C28: CHANDLER TECHNOLOGY CENTER | D28: 7408 W Detroit St | E28: 170 | F28: Chandler, AZ 85226 | G28: 4581 | H28: AutoJoy, Inc | K28: =G28*L28 -> 6413.4 | L28: 1.4 | N28: 0.1 | O28: No TI, No Free rent,Gold Trust Realty, Base Year Gross, Expansion | P28: 2 | Q28: 46022 | R28: 45717
A29: New | B29: 341 | C29: CHANDLER TECHNOLOGY CENTER | D29: 7408 W Detroit Street Suite 170 | E29: 170 | F29: Lease | G29: 4581 | H29: Autojoy Inc | K29: =G29*L29 -> 6413.4 | L29: 1.4 | N29: 0.1 | P29: 2 | R29: 45719
A30: R | B30: 341 | C30: CHANDLER TECHNOLOGY CENTER | D30: 7406 W Detroit | F30: Chandler, AZ | G30: 39285 | H30: Daifuku Cleanroom America Corporation | I30: 41642.1 | J30: =I30/G30 -> 1.06 | K30: 44784.9 | L30: =K30/G30 -> 1.14 | M30: =(K30/I30)-1 -> 0.075471698 | N30: 0.03 | O30: TI, 2 Months free, Marc Pierce (Lee), Base Year | P30: 7 | Q30: 45777 | R30: 45778
A31: R | B31: 341 | C31: CHANDLER TECHNOLOGY CENTER | D31: 7404 W Detroit | E31: 140 | F31: Chandler, AZ 85226 | G31: 12730 | H31: Med Fibers, Inc | I31: 14512.2 | J31: =I31/G31 -> 1.14 | K31: 16167.1 | L31: =K31/G31 -> 1.27 | M31: =(K31/I31)-1 -> 0.11403509 | N31: 0.06 | O31: No TI, No Free rent, No outside agent, Base Year Gross | P31: 5 | Q31: 46022 | R31: 46023
A32: R | B32: 341 | C32: CHANDLER TECHNOLOGY CENTER | D32: 7400 W Detroit | E32: 160 | F32: Chandler, AZ | G32: 1525 | H32: SO Esthetics, LLC | I32: 1601.25 | J32: =I32/G32 -> 1.05 | K32: 1677.5 | L32: =K32/G32 -> 1.1 | M32: =(K32/I32)-1 -> 0.047619048 | O32: No TI, No Free rent, No outside agent, Base Year Gross | P32: 1 | Q32: 46081 | R32: 46082
A33: R | B33: 350 | C33: Chicago Business Park | D33: 6710 W Chicago St | E33: 3 | F33: Chandler, AZ | G33: 2804 | H33: Ameri-Sol, LLC | I33: 3056.36 | J33: =I33/G33 -> 1.09 | K33: 3757.36 | L33: =K33/G33 -> 1.34 | M33: =(K33/I33)-1 -> 0.2293578 | N33: 0.07 | O33: No TI, 1 Mo Free rent (tenant to replace EVAP), No outside agent, Base Year Gross | P33: 3 | Q33: 45838 | R33: 45839
A34: R | B34: 350 | C34: Chicago Business Park | D34: 6700 W Chicago | E34: 5 | F34: Chandler, 85226 | G34: 2487 | H34: WATER SYSTEMS SOLUTIONS, LLC | I34: 2860.05 | J34: =I34/G34 -> 1.15 | K34: 3208.23 | L34: =K34/G34 -> 1.29 | M34: =(K34/I34)-1 -> 0.12173913 | N34: 0.06 | O34: No TI, No Free rent, No outside agent, Base Year Gross | P34: 5 | Q34: 45900 | R34: 45901
A35: R | B35: 350 | C35: Chicago Business Park | D35: 6730 W Chicago St | E35: 4, 5 | F35: Contract | G35: 21320 | H35: Scriven Precision Fabricating | I35: 21054.32 | J35: =I35/G35 -> 0.98753846 | K35: 23452 | L35: =K35/G35 -> 1.1 | M35: =(K35/I35)-1 -> 0.11388067 | N35: 0.05 | O35: No TI, No Free rent, Kathleen Hampton, Base Year Gross | P35: 3 | Q35: 45747 | R35: 45901
A36: New | B36: 350 | C36: Chicago Business Park | D36: 6710 W Chicago Street, Suite 5 | E36: 5 | F36: Lease | G36: 1574 | H36: Happy Jack Distillers, LLC | K36: =G36*L36 -> 2140.64 | L36: 1.36 | N36: 0.04 | O36: 2 | P36: 5 | R36: 45992
A37: New | B37: 350 | C37: Chicago Business Park | D37: 6730 W Chicago Street, Suite 1 | E37: 1 | F37: Lease | G37: 1574 | H37: Steel & Grace Overhead Doors LLC | K37: =G37*L37 -> 2172.12 | L37: 1.38 | N37: 0.06 | P37: 2 | R37: 45992
A38: R | B38: 350 | C38: Chicago Business Park | D38: 6700 W Chicago | E38: 4 | F38: Chandler, AZ 85226 | G38: 2487 | H38: CELTIC FORKLIFT, INC. | I38: 2860.05 | J38: =I38/G38 -> 1.15 | K38: 3456.93 | L38: =K38/G38 -> 1.39 | M38: =(K38/I38)-1 -> 0.20869565 | O38: No TI, No Free rent, No outside agent, Base Year Gross | P38: 1 | Q38: 45991 | R38: 45992
A39: RX | B39: 370 | C39: Deer Valley Commerce Center | D39: 1725 W Williams Dr | F39: Phoenix, AZ 85027 | G39: 11700 | H39: Cornel Hasna | I39: 9740.25 | J39: =I39/G39 -> 0.8325 | K39: 16029 | L39: =K39/G39 -> 1.37 | M39: 0.23 | N39: 0.06 | O39: Tenant is expanding and renewing their lease. They will now have suites 25, 26, 27, 28 and have renewed for 3 years | P39: 3 | Q39: 45716 | R39: 45717
A40: New | B40: 370 | C40: Deer Valley Commerce Center | D40: 1725 W Williams Dr | E40: 57,58 | F40: Lease | G40: 5850 | H40: Maverix Baseball Academy LLC | K40: =G40*L40 -> 8482.5 | L40: 1.45 | N40: 0.05 | O40: 2 | P40: 5 | R40: 45809
...

Sheet 120_Golden Key Plaza
A1: Golden Key Plaza | C1: 120 | D1: 2 | F1: =IFERROR(MATCH($C$1,'Working - CPI'!$A:$A,0),"") -> 224 | G1: =IFERROR(MATCH($C$1,'Lease Report 2025'!$B:$B,0),"") -> 2 | T1: Leasing Pipeline Report
A2: Gilbert, Arizona | C2: =IF(G2=0,"",(G2-E47)/G2) -> 0.94261858 | D2: % Occupancy | F2: SF | G2: ='Occupancy Summary Schedule'!$D$13 -> 63714 | U2: =TODAY() -> 46009 | AH2: SF Threshold
A3: ='Occupancy Summary Schedule'!F53 -> 0.88710744 | B3: % CPI Portfolio Occupancy | AH3: 5000
A4: Active Lease Deals | W4: NER Calculations | AJ4: # | AK4: List
G5: RENT | J5: TERM | L5: TI | N5: Free Rent | P5: Bumps (%) | Q5: LCs | R5: NER | S5: NER Check | V5: NER Check | W5: Subtotals | AB5: Budget / Actual | AE5: Term | AJ5: 0 | AK5: Good | AM5: Raleigh Light Industrial - Rent Bump Calculation | BD5: Raleigh Light Industrial - Rent Bump Calculation (Monthly Rents)
A6: Broker | B6: Tenant | C6: Building | D6: Suite | E6: SF | F6: Type | G6: Current | H6: CPI Proj | I6: Proposed | J6: Budget | K6: Proposed | L6: Budget | M6: Proposed | N6: Budget | O6: Proposed | P6: Proposed | Q6: Proposed | R6: Proposed | T6: Expiration | U6: Comments | W6: Revenue | X6: Bumps | Y6: TIs | Z6: LCs | AA6: FR | AB6: Rent | AC6: FR | AD6: TI | AE6: Years | AF6: Month | AG6: Total | AH6: Term Check | AJ6: 1 | AK6: Check Term | AL6: Month: | AM6: 12 | AN6: =AM6+12 -> 24 | AO6: =AN6+12 -> 36 | AP6: =AO6+12 -> 48 | AQ6: =AP6+12 -> 60 | AR6: =AQ6+12 -> 72 | AS6: =AR6+12 -> 84 | AT6: =AS6+12 -> 96 | AU6: =AT6+12 -> 108 | ... BB6: =BA6+12 -> 192 | BD6: =AM6 -> 12 | BE6: =AN6 -> 24 | BF6: =AO6 -> 36 | BG6: =AP6 -> 48 | BH6: =AQ6 -> 60 | BI6: =AR6 -> 72 | BJ6: =AS6 -> 84 | BK6: =AT6 -> 96 | ... BS6: =BB6 -> 192
W7: =AB7*E7*(AG7/12) -> 0 | X7: =SUMIFS($AM7:$BB7,$AM$6:$BB$6,"<="&AG7)+(INDEX($BD7:$BS7,MATCH(AG7+12,$AM$6:$BB$6))*(AG7-INDEX($AM$6:$BB$6,MATCH(AG7,$AM$6:$BB$6))))-W7 -> #N/A | Y7: =AD7*E7 -> 0 | Z7: =SUM(W7:X7)*Q7 -> #N/A | AA7: =AB7/12*E7*AC7 -> 0 | AB7: =IF(I7="",H7,I7) -> 0 | AC7: =IF(O7="",N7,O7) -> 0 | AD7: =IF(M7="",L7,M7) -> 0 | AE7: =IFERROR(LEFT(K7, FIND("-", K7) - 1),J7) -> 0 | AF7: =IFERROR(RIGHT(K7,LEN(K7)-SEARCH("-",K7)),0) -> 0 | AG7: =_xlfn.NUMBERVALUE(AE7)*12+_xlfn.NUMBERVALUE(AF7) -> 0 | AH7: =IF(E7<$AH$3,36,60) -> 36 | AJ7: 2 | AK7: Check | AM7: =AB7*$E7 -> 0 | AN7: =AM7*(1+$P7) -> 0 | AO7: =AN7*(1+$P7) -> 0 | AP7: =AO7*(1+$P7) -> 0 | AQ7: =AP7*(1+$P7) -> 0 | AR7: =AQ7*(1+$P7) -> 0 | AS7: =AR7*(1+$P7) -> 0 | AT7: =AS7*(1+$P7) -> 0 | AU7: =AT7*(1+$P7) -> 0 | ... BB7: =BA7*(1+$P7) -> 0 | BD7: =AM7/12 -> 0 | BE7: =AN7/12 -> 0 | BF7: =AO7/12 -> 0 | BG7: =AP7/12 -> 0 | BH7: =AQ7/12 -> 0 | BI7: =AR7/12 -> 0 | BJ7: =AS7/12 -> 0 | BK7: =AT7/12 -> 0 | ... BS7: =BB7/12 -> 0
W9: =AB9*E9*(AG9/12) -> 0 | X9: =SUMIFS($AM9:$BB9,$AM$6:$BB$6,"<="&AG9)+(INDEX($BD9:$BS9,MATCH(AG9+12,$AM$6:$BB$6))*(AG9-INDEX($AM$6:$BB$6,MATCH(AG9,$AM$6:$BB$6))))-W9 -> #N/A | Y9: =AD9*E9 -> 0 | Z9: =SUM(W9:X9)*Q9 -> #N/A | AA9: =AB9/12*E9*AC9 -> 0 | AB9: =IF(I9="",H9,I9) -> 0 | AC9: =IF(O9="",N9,O9) -> 0 | AD9: =IF(M9="",L9,M9) -> 0 | AE9: =IFERROR(LEFT(K9, FIND("-", K9) - 1),J9) -> 0 | AF9: =IFERROR(RIGHT(K9,LEN(K9)-SEARCH("-",K9)),0) -> 0 | AG9: =_xlfn.NUMBERVALUE(AE9)*12+_xlfn.NUMBERVALUE(AF9) -> 0 | AH9: =IF(E9<$AH$3,36,60) -> 36 | AM9: =AB9*$E9 -> 0 | AN9: =AM9*(1+$P9) -> 0 | AO9: =AN9*(1+$P9) -> 0 | AP9: =AO9*(1+$P9) -> 0 | AQ9: =AP9*(1+$P9) -> 0 | AR9: =AQ9*(1+$P9) -> 0 | AS9: =AR9*(1+$P9) -> 0 | AT9: =AS9*(1+$P9) -> 0 | AU9: =AT9*(1+$P9) -> 0 | ... BB9: =BA9*(1+$P9) -> 0 | BD9: =AM9/12 -> 0 | BE9: =AN9/12 -> 0 | BF9: =AO9/12 -> 0 | BG9: =AP9/12 -> 0 | BH9: =AQ9/12 -> 0 | BI9: =AR9/12 -> 0 | BJ9: =AS9/12 -> 0 | BK9: =AT9/12 -> 0 | ... BS9: =BB9/12 -> 0
W10: =AB10*E10*(AG10/12) -> 0 | X10: =SUMIFS($AM10:$BB10,$AM$6:$BB$6,"<="&AG10)+(INDEX($BD10:$BS10,MATCH(AG10+12,$AM$6:$BB$6))*(AG10-INDEX($AM$6:$BB$6,MATCH(AG10,$AM$6:$BB$6))))-W10 -> #N/A | Y10: =AD10*E10 -> 0 | Z10: =SUM(W10:X10)*Q10 -> #N/A | AA10: =AB10/12*E10*AC10 -> 0 | AB10: =IF(I10="",H10,I10) -> 0 | AC10: =IF(O10="",N10,O10) -> 0 | AD10: =IF(M10="",L10,M10) -> 0 | AE10: =IFERROR(LEFT(K10, FIND("-", K10) - 1),J10) -> 0 | AF10: =IFERROR(RIGHT(K10,LEN(K10)-SEARCH("-",K10)),0) -> 0 | AG10: =_xlfn.NUMBERVALUE(AE10)*12+_xlfn.NUMBERVALUE(AF10) -> 0 | AH10: =IF(E10<$AH$3,36,60) -> 36 | AM10: =AB10*$E10 -> 0 | AN10: =AM10*(1+$P10) -> 0 | AO10: =AN10*(1+$P10) -> 0 | AP10: =AO10*(1+$P10) -> 0 | AQ10: =AP10*(1+$P10) -> 0 | AR10: =AQ10*(1+$P10) -> 0 | AS10: =AR10*(1+$P10) -> 0 | AT10: =AS10*(1+$P10) -> 0 | AU10: =AT10*(1+$P10) -> 0 | ... BB10: =BA10*(1+$P10) -> 0 | BD10: =AM10/12 -> 0 | BE10: =AN10/12 -> 0 | BF10: =AO10/12 -> 0 | BG10: =AP10/12 -> 0 | BH10: =AQ10/12 -> 0 | BI10: =AR10/12 -> 0 | BJ10: =AS10/12 -> 0 | BK10: =AT10/12 -> 0 | ... BS10: =BB10/12 -> 0
A11: Tenants Expiring - Next 6 months
A13: Broker | B13: Tenant | C13: Building | D13: Suite | E13: SF | F13: Expires | G13: Current | H13: Budget | I13: Proposed 3 Year | J13: Proposed 5 Year | K13: Notes | W13: Revenue | X13: Bumps | Y13: TIs | Z13: LCs | AA13: FR | AB13: Rent | AC13: FR | AD13: TI | AE13: Years | AF13: Month | AG13: Total | AH13: Term Check | AJ13: 1 | AK13: Check Term | AL13: Month: | AM13: 12 | AN13: =AM13+12 -> 24 | AO13: =AN13+12 -> 36 | AP13: =AO13+12 -> 48 | AQ13: =AP13+12 -> 60 | AR13: =AQ13+12 -> 72 | AS13: =AR13+12 -> 84 | AT13: =AS13+12 -> 96 | AU13: =AT13+12 -> 108 | ... BB13: =BA13+12 -> 192 | BD13: =AM13 -> 12 | BE13: =AN13 -> 24 | BF13: =AO13 -> 36 | BG13: =AP13 -> 48 | BH13: =AQ13 -> 60 | BI13: =AR13 -> 72 | BJ13: =AS13 -> 84 | BK13: =AT13 -> 96 | ... BS13: =BB13 -> 192
B14: =IF($D$1="","",IF(INDEX('January 2026 Renewals'!$A:$A,$D$1+ROW()-ROW($B$14))<>$C$1,"",INDEX('January 2026 Renewals'!$H:$H,$D$1+ROW()-ROW($B$14)))) -> Essen Floors LLC | C14: =IF($D$1="","",IF(INDEX('January 2026 Renewals'!$A:$A,$D$1+ROW()-ROW($B$14))<>$C$1,"",INDEX('January 2026 Renewals'!$C:$C,$D$1+ROW()-ROW($B$14)))) -> 751-121 | D14: =IF($D$1="","",IF(INDEX('January 2026 Renewals'!$A:$A,$D$1+ROW()-ROW($B$14))<>$C$1,"",INDEX('January 2026 Renewals'!$E:$E,$D$1+ROW()-ROW($B$14)))) -> 121 | E14: =IF($D$1="","",IF(INDEX('January 2026 Renewals'!$A:$A,$D$1+ROW()-ROW($B$14))<>$C$1,"",INDEX('January 2026 Renewals'!$G:$G,$D$1+ROW()-ROW($B$14)))) -> 1191 | F14: =IF($D$1="","",IF(INDEX('January 2026 Renewals'!$A:$A,$D$1+ROW()-ROW($B$14))<>$C$1,"",INDEX('January 2026 Renewals'!$I:$I,$D$1+ROW()-ROW($B$14)))) -> 46053 | G14: =IF($D$1="","",IF(INDEX('January 2026 Renewals'!$A:$A,$D$1+ROW()-ROW($B$14))<>$C$1,"",INDEX('January 2026 Renewals'!$Q:$Q,$D$1+ROW()-ROW($B$14)))) -> 1.4 | H14: =IF($D$1="","",IF(INDEX('January 2026 Renewals'!$A:$A,$D$1+ROW()-ROW($B$14))<>$C$1,"",INDEX('January 2026 Renewals'!$R:$R,$D$1+ROW()-ROW($B$14)))) -> 1.4 | I14: =IF($D$1="","",IF(INDEX('January 2026 Renewals'!$A:$A,$D$1+ROW()-ROW($B$14))<>$C$1,"",INDEX('January 2026 Renewals'!$W:$W,$D$1+ROW()-ROW($B$14)))) -> 1.47 | J14: =IF($D$1="","",IF(INDEX('January 2026 Renewals'!$A:$A,$D$1+ROW()-ROW($B$14))<>$C$1,"",INDEX('January 2026 Renewals'!$AC:$AC,$D$1+ROW()-ROW($B$14)))) -> 1.47 | K14: =IF($D$1="","",IF(INDEX('January 2026 Renewals'!$A:$A,$D$1+ROW()-ROW($B$14))<>$C$1,"",INDEX('January 2026 Renewals'!$AM:$AM,$D$1+ROW()-ROW($B$14)))) -> 12.8.25 Follow up Email
B15: =IF($D$1="","",IF(INDEX('January 2026 Renewals'!$A:$A,$D$1+ROW()-ROW($B$14))<>$C$1,"",INDEX('January 2026 Renewals'!$H:$H,$D$1+ROW()-ROW($B$14)))) -> FLY PROMOTIONS LLC | C15: =IF($D$1="","",IF(INDEX('January 2026 Renewals'!$A:$A,$D$1+ROW()-ROW($B$14))<>$C$1,"",INDEX('January 2026 Renewals'!$C:$C,$D$1+ROW()-ROW($B$14)))) -> 751-111 | D15: =IF($D$1="","",IF(INDEX('January 2026 Renewals'!$A:$A,$D$1+ROW()-ROW($B$14))<>$C$1,"",INDEX('January 2026 Renewals'!$E:$E,$D$1+ROW()-ROW($B$14)))) -> 111 | E15: =IF($D$1="","",IF(INDEX('January 2026 Renewals'!$A:$A,$D$1+ROW()-ROW($B$14))<>$C$1,"",INDEX('January 2026 Renewals'!$G:$G,$D$1+ROW()-ROW($B$14)))) -> 1191 | F15: =IF($D$1="","",IF(INDEX('January 2026 Renewals'!$A:$A,$D$1+ROW()-ROW($B$14))<>$C$1,"",INDEX('January 2026 Renewals'!$I:$I,$D$1+ROW()-ROW($B$14)))) -> 46053 | G15: =IF($D$1="","",IF(INDEX('January 2026 Renewals'!$A:$A,$D$1+ROW()-ROW($B$14))<>$C$1,"",INDEX('January 2026 Renewals'!$Q:$Q,$D$1+ROW()-ROW($B$14)))) -> 1.47 | H15: =IF($D$1="","",IF(INDEX('January 2026 Renewals'!$A:$A,$D$1+ROW()-ROW($B$14))<>$C$1,"",INDEX('January 2026 Renewals'!$R:$R,$D$1+ROW()-ROW($B$14)))) -> 1.4 | I15: =IF($D$1="","",IF(INDEX('January 2026 Renewals'!$A:$A,$D$1+ROW()-ROW($B$14))<>$C$1,"",INDEX('January 2026 Renewals'!$W:$W,$D$1+ROW()-ROW($B$14)))) -> 1.54 | J15: =IF($D$1="","",IF(INDEX('January 2026 Renewals'!$A:$A,$D$1+ROW()-ROW($B$14))<>$C$1,"",INDEX('January 2026 Renewals'!$AC:$AC,$D$1+ROW()-ROW($B$14)))) -> 1.54 | K15: =IF($D$1="","",IF(INDEX('January 2026 Renewals'!$A:$A,$D$1+ROW()-ROW($B$14))<>$C$1,"",INDEX('January 2026 Renewals'!$AM:$AM,$D$1+ROW()-ROW($B$14)))) -> 12.8.25 Follow up Email
B16: =IF($D$1="","",IF(INDEX('January 2026 Renewals'!$A:$A,$D$1+ROW()-ROW($B$14))<>$C$1,"",INDEX('January 2026 Renewals'!$H:$H,$D$1+ROW()-ROW($B$14)))) -> Samuel Coffey and Brianne Coffey | C16: =IF($D$1="","",IF(INDEX('January 2026 Renewals'!$A:$A,$D$1+ROW()-ROW($B$14))<>$C$1,"",INDEX('January 2026 Renewals'!$C:$C,$D$1+ROW()-ROW($B$14)))) -> 751-117 | D16: =IF($D$1="","",IF(INDEX('January 2026 Renewals'!$A:$A,$D$1+ROW()-ROW($B$14))<>$C$1,"",INDEX('January 2026 Renewals'!$E:$E,$D$1+ROW()-ROW($B$14)))) -> 117 | E16: =IF($D$1="","",IF(INDEX('January 2026 Renewals'!$A:$A,$D$1+ROW()-ROW($B$14))<>$C$1,"",INDEX('January 2026 Renewals'!$G:$G,$D$1+ROW()-ROW($B$14)))) -> 1191 | F16: =IF($D$1="","",IF(INDEX('January 2026 Renewals'!$A:$A,$D$1+ROW()-ROW($B$14))<>$C$1,"",INDEX('January 2026 Renewals'!$I:$I,$D$1+ROW()-ROW($B$14)))) -> 46081 | G16: =IF($D$1="","",IF(INDEX('January 2026 Renewals'!$A:$A,$D$1+ROW()-ROW($B$14))<>$C$1,"",INDEX('January 2026 Renewals'!$Q:$Q,$D$1+ROW()-ROW($B$14)))) -> 1.47 | H16: =IF($D$1="","",IF(INDEX('January 2026 Renewals'!$A:$A,$D$1+ROW()-ROW($B$14))<>$C$1,"",INDEX('January 2026 Renewals'!$R:$R,$D$1+ROW()-ROW($B$14)))) -> 1.4 | I16: =IF($D$1="","",IF(INDEX('January 2026 Renewals'!$A:$A,$D$1+ROW()-ROW($B$14))<>$C$1,"",INDEX('January 2026 Renewals'!$W:$W,$D$1+ROW()-ROW($B$14)))) -> 1.54 | J16: =IF($D$1="","",IF(INDEX('January 2026 Renewals'!$A:$A,$D$1+ROW()-ROW($B$14))<>$C$1,"",INDEX('January 2026 Renewals'!$AC:$AC,$D$1+ROW()-ROW($B$14)))) -> 1.54 | K16: =IF($D$1="","",IF(INDEX('January 2026 Renewals'!$A:$A,$D$1+ROW()-ROW($B$14))<>$C$1,"",INDEX('January 2026 Renewals'!$AM:$AM,$D$1+ROW()-ROW($B$14)))) -> Terminating
B17: =IF($D$1="","",IF(INDEX('January 2026 Renewals'!$A:$A,$D$1+ROW()-ROW($B$14))<>$C$1,"",INDEX('January 2026 Renewals'!$H:$H,$D$1+ROW()-ROW($B$14)))) -> Innovative Cutting Systems | C17: =IF($D$1="","",IF(INDEX('January 2026 Renewals'!$A:$A,$D$1+ROW()-ROW($B$14))<>$C$1,"",INDEX('January 2026 Renewals'!$C:$C,$D$1+ROW()-ROW($B$14)))) -> 425-105/761-102 | D17: =IF($D$1="","",IF(INDEX('January 2026 Renewals'!$A:$A,$D$1+ROW()-ROW($B$14))<>$C$1,"",INDEX('January 2026 Renewals'!$E:$E,$D$1+ROW()-ROW($B$14)))) -> Base | E17: =IF($D$1="","",IF(INDEX('January 2026 Renewals'!$A:$A,$D$1+ROW()-ROW($B$14))<>$C$1,"",INDEX('January 2026 Renewals'!$G:$G,$D$1+ROW()-ROW($B$14)))) -> 4173 | F17: =IF($D$1="","",IF(INDEX('January 2026 Renewals'!$A:$A,$D$1+ROW()-ROW($B$14))<>$C$1,"",INDEX('January 2026 Renewals'!$I:$I,$D$1+ROW()-ROW($B$14)))) -> 46203 | G17: =IF($D$1="","",IF(INDEX('January 2026 Renewals'!$A:$A,$D$1+ROW()-ROW($B$14))<>$C$1,"",INDEX('January 2026 Renewals'!$Q:$Q,$D$1+ROW()-ROW($B$14)))) -> 1.27 | H17: =IF($D$1="","",IF(INDEX('January 2026 Renewals'!$A:$A,$D$1+ROW()-ROW($B$14))<>$C$1,"",INDEX('January 2026 Renewals'!$R:$R,$D$1+ROW()-ROW($B$14)))) -> 1.4 | I17: =IF($D$1="","",IF(INDEX('January 2026 Renewals'!$A:$A,$D$1+ROW()-ROW($B$14))<>$C$1,"",INDEX('January 2026 Renewals'!$W:$W,$D$1+ROW()-ROW($B$14)))) -> 1.37 | J17: =IF($D$1="","",IF(INDEX('January 2026 Renewals'!$A:$A,$D$1+ROW()-ROW($B$14))<>$C$1,"",INDEX('January 2026 Renewals'!$AC:$AC,$D$1+ROW()-ROW($B$14)))) -> 1.36 | K17: =IF($D$1="","",IF(INDEX('January 2026 Renewals'!$A:$A,$D$1+ROW()-ROW($B$14))<>$C$1,"",INDEX('January 2026 Renewals'!$AM:$AM,$D$1+ROW()-ROW($B$14)))) -> 0
B18: =IF($D$1="","",IF(INDEX('January 2026 Renewals'!$A:$A,$D$1+ROW()-ROW($B$14))<>$C$1,"",INDEX('January 2026 Renewals'!$H:$H,$D$1+ROW()-ROW($B$14)))) | C18: =IF($D$1="","",IF(INDEX('January 2026 Renewals'!$A:$A,$D$1+ROW()-ROW($B$14))<>$C$1,"",INDEX('January 2026 Renewals'!$C:$C,$D$1+ROW()-ROW($B$14)))) | D18: =IF($D$1="","",IF(INDEX('January 2026 Renewals'!$A:$A,$D$1+ROW()-ROW($B$14))<>$C$1,"",INDEX('January 2026 Renewals'!$E:$E,$D$1+ROW()-ROW($B$14)))) | E18: =IF($D$1="","",IF(INDEX('January 2026 Renewals'!$A:$A,$D$1+ROW()-ROW($B$14))<>$C$1,"",INDEX('January 2026 Renewals'!$G:$G,$D$1+ROW()-ROW($B$14)))) | F18: =IF($D$1="","",IF(INDEX('January 2026 Renewals'!$A:$A,$D$1+ROW()-ROW($B$14))<>$C$1,"",INDEX('January 2026 Renewals'!$I:$I,$D$1+ROW()-ROW($B$14)))) | G18: =IF($D$1="","",IF(INDEX('January 2026 Renewals'!$A:$A,$D$1+ROW()-ROW($B$14))<>$C$1,"",INDEX('January 2026 Renewals'!$Q:$Q,$D$1+ROW()-ROW($B$14)))) | H18: =IF($D$1="","",IF(INDEX('January 2026 Renewals'!$A:$A,$D$1+ROW()-ROW($B$14))<>$C$1,"",INDEX('January 2026 Renewals'!$R:$R,$D$1+ROW()-ROW($B$14)))) | I18: =IF($D$1="","",IF(INDEX('January 2026 Renewals'!$A:$A,$D$1+ROW()-ROW($B$14))<>$C$1,"",INDEX('January 2026 Renewals'!$W:$W,$D$1+ROW()-ROW($B$14)))) | J18: =IF($D$1="","",IF(INDEX('January 2026 Renewals'!$A:$A,$D$1+ROW()-ROW($B$14))<>$C$1,"",INDEX('January 2026 Renewals'!$AC:$AC,$D$1+ROW()-ROW($B$14)))) | K18: =IF($D$1="","",IF(INDEX('January 2026 Renewals'!$A:$A,$D$1+ROW()-ROW($B$14))<>$C$1,"",INDEX('January 2026 Renewals'!$AM:$AM,$D$1+ROW()-ROW($B$14))))
B19: =IF($D$1="","",IF(INDEX('January 2026 Renewals'!$A:$A,$D$1+ROW()-ROW($B$14))<>$C$1,"",INDEX('January 2026 Renewals'!$H:$H,$D$1+ROW()-ROW($B$14)))) | C19: =IF($D$1="","",IF(INDEX('January 2026 Renewals'!$A:$A,$D$1+ROW()-ROW($B$14))<>$C$1,"",INDEX('January 2026 Renewals'!$C:$C,$D$1+ROW()-ROW($B$14)))) | D19: =IF($D$1="","",IF(INDEX('January 2026 Renewals'!$A:$A,$D$1+ROW()-ROW($B$14))<>$C$1,"",INDEX('January 2026 Renewals'!$E:$E,$D$1+ROW()-ROW($B$14)))) | E19: =IF($D$1="","",IF(INDEX('January 2026 Renewals'!$A:$A,$D$1+ROW()-ROW($B$14))<>$C$1,"",INDEX('January 2026 Renewals'!$G:$G,$D$1+ROW()-ROW($B$14)))) | F19: =IF($D$1="","",IF(INDEX('January 2026 Renewals'!$A:$A,$D$1+ROW()-ROW($B$14))<>$C$1,"",INDEX('January 2026 Renewals'!$I:$I,$D$1+ROW()-ROW($B$14)))) | G19: =IF($D$1="","",IF(INDEX('January 2026 Renewals'!$A:$A,$D$1+ROW()-ROW($B$14))<>$C$1,"",INDEX('January 2026 Renewals'!$Q:$Q,$D$1+ROW()-ROW($B$14)))) | H19: =IF($D$1="","",IF(INDEX('January 2026 Renewals'!$A:$A,$D$1+ROW()-ROW($B$14))<>$C$1,"",INDEX('January 2026 Renewals'!$R:$R,$D$1+ROW()-ROW($B$14)))) | I19: =IF($D$1="","",IF(INDEX('January 2026 Renewals'!$A:$A,$D$1+ROW()-ROW($B$14))<>$C$1,"",INDEX('January 2026 Renewals'!$W:$W,$D$1+ROW()-ROW($B$14)))) | J19: =IF($D$1="","",IF(INDEX('January 2026 Renewals'!$A:$A,$D$1+ROW()-ROW($B$14))<>$C$1,"",INDEX('January 2026 Renewals'!$AC:$AC,$D$1+ROW()-ROW($B$14)))) | K19: =IF($D$1="","",IF(INDEX('January 2026 Renewals'!$A:$A,$D$1+ROW()-ROW($B$14))<>$C$1,"",INDEX('January 2026 Renewals'!$AM:$AM,$D$1+ROW()-ROW($B$14))))
